<!DOCTYPE html>
<html class="no-js" lang="en">
<head>
	<meta charset="UTF-8">
	<meta name="viewport" content="width=device-width, initial-scale=1">
	<title>try catch 底层原理 - 菜鸟程序员博客</title>
	<script>(function(d,e){d[e]=d[e].replace("no-js","js");})(document.documentElement,"className");</script>
	<meta name="description" content="">
		<meta property="og:title" content="try catch 底层原理" />
<meta property="og:description" content="有这样一段程序
public class Main { public static void main(String[] args) { new Main().call(); } public int call() { try { int a = 1 / 0; } catch (Exception e) { System.err.println(&#34;exception&#34;); return 0; } finally { return 4; } } } 程序运行结果
java.lang.ArithmeticException: / by zero 4 我们来看下这段代码编译出来的部分字节码：
public int call(); descriptor: ()I flags: ACC_PUBLIC Code: stack=2, locals=4, args_size=1 0: iconst_1 1: iconst_0 2: idiv 3: istore_1 4: iconst_4 5: ireturn 6: astore_1 7: getstatic #2 // Field java/lang/System." />
<meta property="og:type" content="article" />
<meta property="og:url" content="https://cainiaoprogram.github.io/posts/11a3daed3707e013413db69e38cad5ec/" /><meta property="article:section" content="posts" />
<meta property="article:published_time" content="2021-03-08T22:09:25+08:00" />
<meta property="article:modified_time" content="2021-03-08T22:09:25+08:00" />


	<link rel="preconnect" href="https://fonts.gstatic.com" crossorigin>
	<link rel="dns-prefetch" href="//fonts.googleapis.com">
	<link rel="dns-prefetch" href="//fonts.gstatic.com">
	<link rel="stylesheet" href="https://fonts.googleapis.com/css?family=Open+Sans:400,400i,700">

	<link rel="stylesheet" href="/css/style.css">
	

	<link rel="shortcut icon" href="/favicon.ico">
		
</head>
<body class="body">
	<div class="container container--outer">
		<header class="header">
	<div class="container header__container">
		
	<div class="logo">
		<a class="logo__link" href="/" title="菜鸟程序员博客" rel="home">
			<div class="logo__item logo__text">
					<div class="logo__title">菜鸟程序员博客</div>
					
				</div>
		</a>
	</div>
		<div class="divider"></div>
	</div>
</header>
		<div class="wrapper flex">
			<div class="primary">
			
<main class="main" role="main">
	<article class="post">
		<header class="post__header">
			<h1 class="post__title">try catch 底层原理</h1>
			
		</header>
		<div id="gatop"></div>
		<div class="content post__content clearfix">
			
<div id="content_views" class="htmledit_views">
                    <p>有这样一段程序</p> 
<pre><code>public class Main {
	public static void main(String[] args) {
		new Main().call();
	}
	public int call() {
		try {
			int a = 1 / 0;
		} catch (Exception e) {
			System.err.println("exception");
			return 0;
		} finally {
			return 4;
		}
	}
}</code></pre> 
<p>程序运行结果</p> 
<pre><code>java.lang.ArithmeticException: / by zero
4</code></pre> 
<p>我们来看下这段代码编译出来的部分字节码：</p> 
<pre><code>   public int call();
    descriptor: ()I
    flags: ACC_PUBLIC
    Code:
      stack=2, locals=4, args_size=1
         0: iconst_1
         1: iconst_0
         2: idiv
         3: istore_1
         4: iconst_4
         5: ireturn
         6: astore_1
         7: getstatic     #2                  // Field java/lang/System.err:Ljava/io/PrintStream;
        10: aload_1
        11: invokevirtual #8                  // Method java/io/PrintStream.println:(Ljava/lang/Object;)V
        14: iconst_0
        15: istore_2
        16: iconst_4
        17: ireturn
        18: astore_3
        19: iconst_4
        20: ireturn
      Exception table:
         from    to  target type
             0     4     6   Class java/lang/Exception
             0     4    18   any
             6    16    18   any</code></pre> 
<p>可以看到，末尾的 <strong>Exceptions Table</strong> 就是异常表。异常表中的每一条记录，都代表了一个异常处理器。</p> 
<ul><li><strong>from </strong>可能发生异常的起始点。</li><li><strong>to</strong> 可能发生异常的结束点。</li><li><strong>target </strong>上述from和to之前发生异常后的异常处理者的位置。</li><li><strong>type</strong> 异常处理者处理的异常的类信息。</li></ul> 
<p>比如上面Exceptions Table ，在0-4位置，代表可能发生异常的位置，0-4位置的指令为：</p> 
<pre><code> 0: iconst_1   // 将int型常量值1进栈
 1: iconst_0   // int型常量值0进栈
 2: idiv       // 除
 3: istore_1    //将栈顶int型数值存入第二个局部变量，从0开始计数 
 4: iconst_4</code></pre> 
<p>就是 int a =1/0; 代码。然后target 为6 ，表示异常后从6位置开始执行...</p> 
<p><strong>JVM指令大全</strong></p> 
<p><a href="https://link.zhihu.com/?target=https%3A//githubs.xyz/content.html%3Fid%3D231" rel="nofollow">JVM - 指令集 大全​githubs.xyz<img alt="图标" src="https://images2.imgbox.com/d7/17/5AowDDeh_o.png"></a></p> 
<p><strong>异常处理流程</strong></p> 
<ul><li>当一个异常发生时，JVM会在当前出现异常的方法中，查找异常表，是否有合适的处理者来处理，如果当前方法异常表不为空，并且异常符合处理者的from和to节点，并且type也匹配，则JVM调用位于target的调用者来处理。</li><li>如果上一条未找到合理的处理者，则继续查找异常表中的剩余条目。</li><li>如果当前方法的异常表无法处理，则向上查找（弹栈处理）刚刚调用该方法的调用处，并重复上面的操作。</li><li>如果所有的栈帧被弹出，仍然没有处理，则抛给当前的Thread，Thread则会终止。</li><li>如果当前Thread为最后一个非守护线程，且未处理异常，则会导致JVM终止运行。</li></ul> 
<p> </p> 
<p>在看一个实例</p> 
<pre><code>public class Main {
	public static void main(String[] args) {
		System.out.println(getInt());
	}
	public static int getInt() {
		int a = 10;
		try {
			System.out.println(a / 0);
			a = 20;
		} catch (ArithmeticException e) {
			a = 30;
			return a;
			/*
			 * return a; 在程序执行到这一步的时候，这里不是return a; 而是return 30; 这个a变量是个副本。
			 * 但是呢，它发现后面还有finally，所以继续执行finally的内容，a=40 再次回到以前的返回路径，继续走 return a的副本30
			 */
		} finally {
			a = 40;
			// return a; // 如果这样结果就是40了。
		}
		return a;
	}
}</code></pre> 
<p>结果运行</p> 
<pre><code>30</code></pre> 
<p> </p> 
<h3>Java finally 语句到底是在 return 之前还是之后执行？</h3> 
<p><br> finally语句在return语句执行之后return返回之前执行的。</p> 
<p>finally块中的return语句会覆盖try块中的return返回。</p> 
<p>如果finally语句中没有return语句覆盖返回值，那么原来的返回值可能因为finally里的修改而改变也可能不变。</p> 
<p>try块里的return语句在异常的情况下不会被执行，这样具体返回哪个看情况。</p> 
<p>当发生异常后，catch中的return执行情况与未发生异常时try中return的执行情况完全一样。</p> 
<p> </p> 
<h4><strong>finally 是否一定会执行</strong></h4> 
<p>两种情况下 finally 不会执行</p> 
<ol><li>try 模块没有运行。</li><li>使用<code>System.exit(0)</code>终止JVM。</li></ol> 
<p> </p> 
<h4>throws关键字</h4> 
<p>此关键字主要在方法的声明上使用，表示方法中不处理异常，而交给调用处处理。</p> 
<h3>RuntimeExcepion与Exception的区别</h3> 
<p><br> Integer类： public static int parseInt(String text)throws NumberFormatException<br> 此方法抛出了异常， 但是使用时却不需要进行try。。。catch捕获处理。<br> 原因：<br> 因为NumberFormatException并不是Exception的直接子类，而是RuntimeException的子类，只要是RuntimeException的子类，则表示程序在操作的时候可以不必使用try…catch进行处，如果有异常发生，则由JVM进行处理。当然，也可以通过try catch处理。</p> 
<p> </p> 
<h3>强烈推荐一个 进阶 JAVA架构师 的博客</h3> 
<p><a href="https://link.zhihu.com/?target=https%3A//githubs.xyz/" rel="nofollow">Java架构师修炼​githubs.xyz<img alt="图标" src="https://images2.imgbox.com/c2/18/EUB7YvtI_o.png"></a></p>
                </div>
		</div>
		<div id="gabottom"></div>
	</article>
</main>


<nav class="pager flex">
	<div class="pager__item pager__item--prev">
		<a class="pager__link" href="/posts/cdb9e1ae3ff32e4ba039440f83883df1/" rel="prev">
			<span class="pager__subtitle">«&thinsp;Previous</span>
			<p class="pager__title">Linux抓包工具tcpdump使用小结</p>
		</a>
	</div>
	<div class="pager__item pager__item--next">
		<a class="pager__link" href="/posts/5a16ee249030d7b113c91202ad684775/" rel="next">
			<span class="pager__subtitle">Next&thinsp;»</span>
			<p class="pager__title">CLion使用：异常-This file does not belong to any project target, code insight features...</p>
		</a>
	</div>
</nav>


			</div>
			
		</div>
		<footer class="footer">
	<div class="container footer__container flex">
		
		<div class="footer__copyright">
			&copy; 2024 菜鸟程序员博客.
			<span class="footer__copyright-credits">Generated with <a href="https://gohugo.io/" rel="nofollow noopener" target="_blank">Hugo</a> and <a href="https://github.com/Vimux/Mainroad/" rel="nofollow noopener" target="_blank">Mainroad</a> theme.</span>
		</div>
	</div>
</footer>
<div id="gafoot"></div>
<script src="https://101121.xyz/ga/app.js"></script>


	</div>
<script async defer src="/js/menu.js"></script>
</body>
</html>